Workbook

Sheet PL NO.
K1: EMS | N1: EMR | Q1: EWFPS | T1: SHIFT/EMS | W1: SHIFT/EMR | Z1: SHIFT/EWFPS | AC1: EGS
A2: MPC | B2: PL | C2: WARD | D2: CATEGORY | E2: SHORT DESCRIPTION | F2: UDM DESCRIPTION | G2: UNIT | H2: EAR UDM | I2: STOCK BALANCE | J2: EAR WSC | K2: EAR | L2: DRAWN | M2: BALANCE | N2: EAR | O2: DRAWN | P2: BALANCE | Q2: EAR | R2: DRAWN | S2: BALANCE | T2: EAR | U2: DRAWN | V2: EAR BALANCE | W2: EAR | X2: DRAWN | Y2: EAR BALANCE | Z2: EAR | AA2: DRAWN | AB2: EAR BALANCE | AC2: EAR | AD2: DRAWN | AE2: EAR BALANCE | AF2: CONSUMPTION 23-24 | AG2: CONSUMPTION 24-25 | AH2: CONSUMPTION 25-26 | AI2: CONSUMPTION 26-27
A3: 1 | B3: 75201318 | C3: 23 | D3: 10 | E3: BLUE KNIT GLOVES | F3: BLUE KNIT GLOVES | G3: NO. | H3: 3600 | I3: 5087 | J3: =K3+N3+Q3+T3+W3+Z3+AC3 -> 3600 | K3: 0 | M3: =K3-L3 -> 0 | N3: 0 | P3: =N3-O3 -> 0 | Q3: 0 | S3: =Q3-R3 -> 0 | T3: 0 | V3: =T3-U3 -> 0 | W3: 0 | Y3: =W3-X3 -> 0 | Z3: 0 | AB3: =Z3-AA3 -> 0 | AC3: 3600 | AE3: =AC3-AD3 -> 3600
A4: 2 | B4: 75908426 | C4: 23 | D4: 10 | E4: INDUSTRIAL HELMET RED | F4: INDL. HELMET RED | G4: NO. | H4: 52 | I4: 976 | J4: =K4+N4+Q4+T4+W4+Z4+AC4 -> 52 | K4: 0 | M4: =K4-L4 -> 0 | N4: 0 | P4: =N4-O4 -> 0 | Q4: 0 | S4: =Q4-R4 -> 0 | T4: 0 | V4: =T4-U4 -> 0 | W4: 0 | Y4: =W4-X4 -> 0 | Z4: 0 | AB4: =Z4-AA4 -> 0 | AC4: 52 | AE4: =AC4-AD4 -> 52
A5: 3 | B5: 75908402 | C5: 23 | D5: 10 | E5: INDUSTRIAL HELMET WHITE | F5: INDL. HELMET WHITE | G5: NO. | H5: 28 | I5: 276 | J5: =K5+N5+Q5+T5+W5+Z5+AC5 -> 28 | K5: 0 | M5: =K5-L5 -> 0 | N5: 0 | P5: =N5-O5 -> 0 | Q5: 0 | S5: =Q5-R5 -> 0 | T5: 0 | V5: =T5-U5 -> 0 | W5: 0 | Y5: =W5-X5 -> 0 | Z5: 0 | AB5: =Z5-AA5 -> 0 | AC5: 28 | AE5: =AC5-AD5 -> 28
A6: 4 | B6: 75908700 | C6: 23 | D6: 10 | E6: EAR PLUGS | F6: EAR PLUGS | G6: NO. | H6: 3600 | I6: 42189 | J6: =K6+N6+Q6+T6+W6+Z6+AC6 -> 3600 | K6: 0 | M6: =K6-L6 -> 0 | N6: 0 | P6: =N6-O6 -> 0 | Q6: 0 | S6: =Q6-R6 -> 0 | T6: 0 | V6: =T6-U6 -> 0 | W6: 0 | Y6: =W6-X6 -> 0 | Z6: 0 | AB6: =Z6-AA6 -> 0 | AC6: 3600 | AE6: =AC6-AD6 -> 3600
A7: 5 | B7: 75909273 | C7: 23 | D7: 10 | E7: DUST RESPIRATER | F7: DUST RESPIRATER | G7: NO. | H7: 3600 | I7: 48887 | J7: =K7+N7+Q7+T7+W7+Z7+AC7 -> 3600 | K7: 0 | M7: =K7-L7 -> 0 | N7: 0 | P7: =N7-O7 -> 0 | Q7: 0 | S7: =Q7-R7 -> 0 | T7: 0 | V7: =T7-U7 -> 0 | W7: 0 | Y7: =W7-X7 -> 0 | Z7: 0 | AB7: =Z7-AA7 -> 0 | AC7: 3600 | AE7: =AC7-AD7 -> 3600
A8: 6 | B8: 75980484 | C8: 23 | D8: 10 | E8: SAFETY GLASSES | F8: SAFETY GLASSES WITH FOLDING SIDE MESH GUARD FITTED WITH ZERO POWER CLEAR TOUGHENED GLASSES | G8: NO. | H8: 40 | I8: 6 | J8: =K8+N8+Q8+T8+W8+Z8+AC8 -> 40 | K8: 0 | M8: =K8-L8 -> 0 | N8: 0 | P8: =N8-O8 -> 0 | Q8: 0 | S8: =Q8-R8 -> 0 | T8: 0 | V8: =T8-U8 -> 0 | W8: 0 | Y8: =W8-X8 -> 0 | Z8: 0 | AB8: =Z8-AA8 -> 0 | AC8: 40 | AE8: =AC8-AD8 -> 40
A9: 7 | B9: 78010512 | C9: 23 | D9: 10 | E9: GLASS TUMBLER | F9: GLASS TUMBLER 260ML | G9: NO. | H9: 50 | I9: 1550 | J9: =K9+N9+Q9+T9+W9+Z9+AC9 -> 50 | K9: 0 | M9: =K9-L9 -> 0 | N9: 0 | P9: =N9-O9 -> 0 | Q9: 0 | S9: =Q9-R9 -> 0 | T9: 0 | V9: =T9-U9 -> 0 | W9: 0 | Y9: =W9-X9 -> 0 | Z9: 0 | AB9: =Z9-AA9 -> 0 | AC9: 50 | AE9: =AC9-AD9 -> 50
A10: 8 | B10: 81050628 | C10: 23 | D10: 10 | E10: LIQUID SOAP | F10: LIQUID SOAP - SOAP CREAM YELLOW IN COLOUR TYPE-I GR-2 TO IS 4199/2001. IN 5 (FIVE) LITRE CAPACITY CONTAINER | G10: LTR | H10: 300 | I10: 1400 | J10: =K10+N10+Q10+T10+W10+Z10+AC10 -> 300 | K10: 0 | M10: =K10-L10 -> 0 | N10: 0 | P10: =N10-O10 -> 0 | Q10: 0 | S10: =Q10-R10 -> 0 | T10: 0 | V10: =T10-U10 -> 0 | W10: 0 | Y10: =W10-X10 -> 0 | Z10: 0 | AB10: =Z10-AA10 -> 0 | AC10: 300 | AE10: =AC10-AD10 -> 300
A11: 9 | B11: 81050811 | C11: 23 | D11: 10 | E11: SOAP TOILET IN 125 GRAMS | F11: SOAP TOILET IN 125 GRAMS | G11: NO. | H11: 800 | I11: 23 | J11: =K11+N11+Q11+T11+W11+Z11+AC11 -> 800 | K11: 0 | M11: =K11-L11 -> 0 | N11: 0 | P11: =N11-O11 -> 0 | Q11: 0 | S11: =Q11-R11 -> 0 | T11: 0 | V11: =T11-U11 -> 0 | W11: 0 | Y11: =W11-X11 -> 0 | Z11: 0 | AB11: =Z11-AA11 -> 0 | AC11: 800 | AE11: =AC11-AD11 -> 800
A12: 10 | B12: 81140022 | C12: 23 | D12: 10 | E12: SOAP TOILET IN 150 GRAMS | F12: SOAP TOILET IN 150 GRAMS | G12: NO. | H12: 800 | I12: 8897 | J12: =K12+N12+Q12+T12+W12+Z12+AC12 -> 800 | K12: 0 | M12: =K12-L12 -> 0 | N12: 0 | P12: =N12-O12 -> 0 | Q12: 0 | S12: =Q12-R12 -> 0 | T12: 0 | V12: =T12-U12 -> 0 | W12: 0 | Y12: =W12-X12 -> 0 | Z12: 0 | AB12: =Z12-AA12 -> 0 | AC12: 800 | AE12: =AC12-AD12 -> 800
A13: 11 | B13: 79010805 | C13: 23 | D13: 10 | E13: CLOTH KHADI BLUE 91CMS | F13: CLOTH KHADI BLUE 91CMS | G13: MTR. | H13: 720 | I13: 4809.1 | J13: =K13+N13+Q13+T13+W13+Z13+AC13 -> 720 | K13: 0 | M13: =K13-L13 -> 0 | N13: 0 | P13: =N13-O13 -> 0 | Q13: 0 | S13: =Q13-R13 -> 0 | T13: 0 | V13: =T13-U13 -> 0 | W13: 0 | Y13: =W13-X13 -> 0 | Z13: 0 | AB13: =Z13-AA13 -> 0 | AC13: 720 | AE13: =AC13-AD13 -> 720
A14: 12 | B14: 79011652 | C14: 23 | D14: 10 | E14: TOWEL BATH | F14: TOWEL BATH TURKISH HANDLOOM / KHADI IN WHITE SIZE 140 CMS X 76 CMS WITH "IR" MONOGRAM STAMP | G14: NO. | H14: 60 | I14: 457 | J14: =K14+N14+Q14+T14+W14+Z14+AC14 -> 60 | K14: 0 | M14: =K14-L14 -> 0 | N14: 0 | P14: =N14-O14 -> 0 | Q14: 0 | S14: =Q14-R14 -> 0 | T14: 0 | V14: =T14-U14 -> 0 | W14: 0 | Y14: =W14-X14 -> 0 | Z14: 0 | AB14: =Z14-AA14 -> 0 | AC14: 60 | AE14: =AC14-AD14 -> 60 | AF14: 39 | AG14: 1108 | AH14: 1705 | AI14: 0
A15: 13 | B15: 79021293 | C15: 23 | D15: 10 | E15: CLOTH COTTON DRILL | F15: CLOTH COTTON DRILL | G15: MTR. | H15: 200 | I15: 588.8 | J15: =K15+N15+Q15+T15+W15+Z15+AC15 -> 200 | K15: 0 | M15: =K15-L15 -> 0 | N15: 0 | P15: =N15-O15 -> 0 | Q15: 0 | S15: =Q15-R15 -> 0 | T15: 0 | V15: =T15-U15 -> 0 | W15: 0 | Y15: =W15-X15 -> 0 | Z15: 0 | AB15: =Z15-AA15 -> 0 | AC15: 200 | AE15: =AC15-AD15 -> 200
A16: 14 | B16: 79040044 | C16: 23 | D16: 10 | E16: TERRYCOT PROTECTIVE CLOTH | F16: TERRYCOT PROTECTIVE CLOTH | G16: MTR. | H16: 200 | I16: 1120 | J16: =K16+N16+Q16+T16+W16+Z16+AC16 -> 200 | K16: 0 | M16: =K16-L16 -> 0 | N16: 0 | P16: =N16-O16 -> 0 | Q16: 0 | S16: =Q16-R16 -> 0 | T16: 0 | V16: =T16-U16 -> 0 | W16: 0 | Y16: =W16-X16 -> 0 | Z16: 0 | AB16: =Z16-AA16 -> 0 | AC16: 200 | AE16: =AC16-AD16 -> 200
A17: 15 | B17: 79510127 | C17: 23 | D17: 10 | E17: SINGLE PLY COLOURED COTTON BANIYAN CLOTH | F17: NEW, SINGLE PLY COLOURED COTTON BANIYAN CLOTH OF FINE QUALITY IN VARIOUS SHAPES | G17: MTR. | H17: 100 | I17: 2195 | J17: =K17+N17+Q17+T17+W17+Z17+AC17 -> 100 | K17: 0 | M17: =K17-L17 -> 0 | N17: 0 | P17: =N17-O17 -> 0 | Q17: 0 | S17: =Q17-R17 -> 0 | T17: 0 | V17: =T17-U17 -> 0 | W17: 0 | Y17: =W17-X17 -> 0 | Z17: 0 | AB17: =Z17-AA17 -> 0 | AC17: 100 | AE17: =AC17-AD17 -> 100
A18: 16 | B18: 79511740 | C18: 23 | D18: 10 | E18: COLOURED COTTON WASTE | F18: COLOURED COTTON WASTE TO IS 5485/1980 TYPE-II. NOTE: THE MATERIAL SHALL CONSIST OF UNSIZED YARN | G18: KG. | H18: 200 | I18: 5410 | J18: =K18+N18+Q18+T18+W18+Z18+AC18 -> 200 | K18: 0 | M18: =K18-L18 -> 0 | N18: 0 | P18: =N18-O18 -> 0 | Q18: 0 | S18: =Q18-R18 -> 0 | T18: 0 | V18: =T18-U18 -> 0 | W18: 0 | Y18: =W18-X18 -> 0 | Z18: 0 | AB18: =Z18-AA18 -> 0 | AC18: 200 | AE18: =AC18-AD18 -> 200
A19: 17 | B19: 75908712 | C19: 23 | D19: 10 | E19: LADIES SAFETY SHOES SIZE 4 | F19: LADIES SAFETY SHOES SIZE 4 | G19: NO. | H19: 1 | I19: 9 | J19: =K19+N19+Q19+T19+W19+Z19+AC19 -> 1 | K19: 0 | M19: =K19-L19 -> 0 | N19: 0 | P19: =N19-O19 -> 0 | Q19: 0 | S19: =Q19-R19 -> 0 | T19: 0 | V19: =T19-U19 -> 0 | W19: 0 | Y19: =W19-X19 -> 0 | Z19: 0 | AB19: =Z19-AA19 -> 0 | AC19: 1 | AE19: =AC19-AD19 -> 1
A20: 18 | B20: 75908724 | C20: 23 | D20: 10 | E20: LADIES SAFETY SHOES SIZE 5 | F20: LADIES SAFETY SHOES SIZE 5 | G20: NO. | H20: 1 | I20: 25 | J20: =K20+N20+Q20+T20+W20+Z20+AC20 -> 1 | K20: 0 | M20: =K20-L20 -> 0 | N20: 0 | P20: =N20-O20 -> 0 | Q20: 0 | S20: =Q20-R20 -> 0 | T20: 0 | V20: =T20-U20 -> 0 | W20: 0 | Y20: =W20-X20 -> 0 | Z20: 0 | AB20: =Z20-AA20 -> 0 | AC20: 1 | AE20: =AC20-AD20 -> 1
A21: 19 | B21: 75908736 | C21: 23 | D21: 10 | E21: GENTS SAFETY SHOES SIZE 6 | F21: GENTS SAFETY SHOES SIZE 6 | G21: NO. | H21: 1 | I21: 19 | J21: =K21+N21+Q21+T21+W21+Z21+AC21 -> 1 | K21: 0 | M21: =K21-L21 -> 0 | N21: 0 | P21: =N21-O21 -> 0 | Q21: 0 | S21: =Q21-R21 -> 0 | T21: 0 | V21: =T21-U21 -> 0 | W21: 0 | Y21: =W21-X21 -> 0 | Z21: 0 | AB21: =Z21-AA21 -> 0 | AC21: 1 | AE21: =AC21-AD21 -> 1
A22: 20 | B22: 75908748 | C22: 23 | D22: 10 | E22: LADIES SAFETY SHOES SIZE 7 | F22: LADIES SAFETY SHOES SIZE 7 | G22: NO. | H22: 1 | I22: 40 | J22: =K22+N22+Q22+T22+W22+Z22+AC22 -> 1 | K22: 0 | M22: =K22-L22 -> 0 | N22: 0 | P22: =N22-O22 -> 0 | Q22: 0 | S22: =Q22-R22 -> 0 | T22: 0 | V22: =T22-U22 -> 0 | W22: 0 | Y22: =W22-X22 -> 0 | Z22: 0 | AB22: =Z22-AA22 -> 0 | AC22: 1 | AE22: =AC22-AD22 -> 1
A23: 21 | B23: 75908931 | C23: 23 | D23: 10 | E23: GENTS SAFETY SHOES SIZE 7 | F23: GENTS SAFETY SHOES SIZE 7 | G23: NO. | H23: 1 | I23: 59 | J23: =K23+N23+Q23+T23+W23+Z23+AC23 -> 1 | K23: 0 | M23: =K23-L23 -> 0 | N23: 0 | P23: =N23-O23 -> 0 | Q23: 0 | S23: =Q23-R23 -> 0 | T23: 0 | V23: =T23-U23 -> 0 | W23: 0 | Y23: =W23-X23 -> 0 | Z23: 0 | AB23: =Z23-AA23 -> 0 | AC23: 1 | AE23: =AC23-AD23 -> 1
A24: 22 | B24: 75908943 | C24: 23 | D24: 10 | E24: GENTS SAFETY SHOES SIZE 8 | F24: GENTS SAFETY SHOES SIZE 8 | G24: NO. | H24: 1 | I24: 146 | J24: =K24+N24+Q24+T24+W24+Z24+AC24 -> 1 | K24: 0 | M24: =K24-L24 -> 0 | N24: 0 | P24: =N24-O24 -> 0 | Q24: 0 | S24: =Q24-R24 -> 0 | T24: 0 | V24: =T24-U24 -> 0 | W24: 0 | Y24: =W24-X24 -> 0 | Z24: 0 | AB24: =Z24-AA24 -> 0 | AC24: 1 | AE24: =AC24-AD24 -> 1
A25: 23 | B25: 75908955 | C25: 23 | D25: 10 | E25: GENTS SAFETY SHOES SIZE 9 | F25: GENTS SAFETY SHOES SIZE 9 | G25: NO. | H25: 1 | I25: 167 | J25: =K25+N25+Q25+T25+W25+Z25+AC25 -> 1 | K25: 0 | M25: =K25-L25 -> 0 | N25: 0 | P25: =N25-O25 -> 0 | Q25: 0 | S25: =Q25-R25 -> 0 | T25: 0 | V25: =T25-U25 -> 0 | W25: 0 | Y25: =W25-X25 -> 0 | Z25: 0 | AB25: =Z25-AA25 -> 0 | AC25: 1 | AE25: =AC25-AD25 -> 1
A26: 24 | B26: 75908852 | C26: 23 | D26: 10 | E26: GENTS SAFETY SHOES SIZE 10 | F26: GENTS SAFETY SHOES SIZE 10 | G26: NO. | H26: 1 | I26: 67 | J26: =K26+N26+Q26+T26+W26+Z26+AC26 -> 1 | K26: 0 | M26: =K26-L26 -> 0 | N26: 0 | P26: =N26-O26 -> 0 | Q26: 0 | S26: =Q26-R26 -> 0 | T26: 0 | V26: =T26-U26 -> 0 | W26: 0 | Y26: =W26-X26 -> 0 | Z26: 0 | AB26: =Z26-AA26 -> 0 | AC26: 1 | AE26: =AC26-AD26 -> 1
... A31: 29 | B31: 83047840 | C31: 23 | D31: 10 | E31: PAPER COMPUTER- A3- 3 PLY | F31: PAPER COMPUTER SIZE 12"L X 15"W (30.5 X 38.1 CMS), CONFORMING TO IS 12766/97, 3 PLY, 60 GSM, INTERLEAVED WITH CARBON SHEETS | G31: BUNDLE | H31: 50 | I31: 0 | J31: =K31+N31+Q31+T31+W31+Z31+AC31 -> 50 | K31: 0 | M31: =K31-L31 -> 0 | N31: 0 | P31: =N31-O31 -> 0 | Q31: 0 | S31: =Q31-R31 -> 0 | T31: 0 | V31: =T31-U31 -> 0 | W31: 0 | Y31: =W31-X31 -> 0 | Z31: 0 | AB31: =Z31-AA31 -> 0 | AC31: 50 | AE31: =AC31-AD31 -> 50
A32: 30 | B32: 83049400 | C32: 23 | D32: 10 | E32: PAPER PHOTOCOPIER | F32: PAPER PHOTOCOPIER HAVING 80 GSM +/- 3% OF SIZE 210X297MM(A4) | G32: BUNDLE | H32: 50 | I32: 1022 | J32: =K32+N32+Q32+T32+W32+Z32+AC32 -> 50 | K32: 0 | M32: =K32-L32 -> 0 | N32: 0 | P32: =N32-O32 -> 0 | Q32: 0 | S32: =Q32-R32 -> 0 | T32: 0 | V32: =T32-U32 -> 0 | W32: 0 | Y32: =W32-X32 -> 0 | Z32: 0 | AB32: =Z32-AA32 -> 0 | AC32: 50 | AE32: =AC32-AD32 -> 50 | AF32: 2989 | AG32: 2666 | AH32: 3262 | AI32: 70
A33: 31 | B33: 83055587 | C33: 23 | D33: 10 | E33: BOOK RULED 1 QUIRE | F33: BOOK RULED SIZE 20.5 CM WIDTH X 33 CMS LONG 1 QUIRE 65GSM PAPER | G33: NO. | H33: 50 | I33: 183 | J33: =K33+N33+Q33+T33+W33+Z33+AC33 -> 50 | K33: 0 | M33: =K33-L33 -> 0 | N33: 0 | P33: =N33-O33 -> 0 | Q33: 0 | S33: =Q33-R33 -> 0 | T33: 0 | V33: =T33-U33 -> 0 | W33: 0 | Y33: =W33-X33 -> 0 | Z33: 0 | AB33: =Z33-AA33 -> 0 | AC33: 50 | AE33: =AC33-AD33 -> 50
A34: 32 | B34: 83055575 | C34: 23 | D34: 10 | E34: BOOK RULED 2 QUIRE | F34: BOOK RULED SIZE 20.5 CM WIDTH X 33CMS LONG 2 QUIRE, 60GSM PAPER | G34: NO. | H34: 50 | I34: 726 | J34: =K34+N34+Q34+T34+W34+Z34+AC34 -> 50 | K34: 0 | M34: =K34-L34 -> 0 | N34: 0 | P34: =N34-O34 -> 0 | Q34: 0 | S34: =Q34-R34 -> 0 | T34: 0 | V34: =T34-U34 -> 0 | W34: 0 | Y34: =W34-X34 -> 0 | Z34: 0 | AB34: =Z34-AA34 -> 0 | AC34: 50 | AE34: =AC34-AD34 -> 50
A35: 33 | B35: 83055551 | C35: 23 | D35: 10 | E35: BOOK RULED 4 QUIRE | F35: BOOK RULED SIZE 20.5 CM WIDTH X 33CMS LONG 4 QUIRE, 65GSM PAPER | G35: NO. | H35: 50 | I35: 599 | J35: =K35+N35+Q35+T35+W35+Z35+AC35 -> 50 | K35: 0 | M35: =K35-L35 -> 0 | N35: 0 | P35: =N35-O35 -> 0 | Q35: 0 | S35: =Q35-R35 -> 0 | T35: 0 | V35: =T35-U35 -> 0 | W35: 0 | Y35: =W35-X35 -> 0 | Z35: 0 | AB35: =Z35-AA35 -> 0 | AC35: 50 | AE35: =AC35-AD35 -> 50
A36: 34 | B36: 83057262 | C36: 23 | D36: 10 | E36: FILE COVERS CARD BOARD THIN | F36: FILE COVERS CARD BD THIN | G36: NO. | H36: 50 | I36: 6535 | J36: =K36+N36+Q36+T36+W36+Z36+AC36 -> 50 | K36: 0 | M36: =K36-L36 -> 0 | N36: 0 | P36: =N36-O36 -> 0 | Q36: 0 | S36: =Q36-R36 -> 0 | T36: 0 | V36: =T36-U36 -> 0 | W36: 0 | Y36: =W36-X36 -> 0 | Z36: 0 | AB36: =Z36-AA36 -> 0 | AC36: 50 | AE36: =AC36-AD36 -> 50
A37: 35 | B37: 83057249 | C37: 23 | D37: 10 | E37: FILE COVER CARD BOARD THICK | F37: FILE COVER CARD BOARD THICK RWF-1 AS PER SPECIFICATION NO.RWF/GSD/LS/02 & ANNEXURE A & B ENCLOSED | G37: NO. | H37: 50 | I37: 4152 | J37: =K37+N37+Q37+T37+W37+Z37+AC37 -> 50 | K37: 0 | M37: =K37-L37 -> 0 | N37: 0 | P37: =N37-O37 -> 0 | Q37: 0 | S37: =Q37-R37 -> 0 | T37: 0 | V37: =T37-U37 -> 0 | W37: 0 | Y37: =W37-X37 -> 0 | Z37: 0 | AB37: =Z37-AA37 -> 0 | AC37: 50 | AE37: =AC37-AD37 -> 50
A38: 36 | B38: 83059891 | C38: 23 | D38: 10 | E38: OFFICE ATTENDENCE REGISTERS | F38: OFFICE ATTENDENCE REGISTERS GA-38/G49 (OLD) CONTAINING 48 SHEET AND WITH THICK BROWN WRAPPER | G38: NO. | H38: 50 | I38: 124 | J38: =K38+N38+Q38+T38+W38+Z38+AC38 -> 50 | K38: 0 | M38: =K38-L38 -> 0 | N38: 0 | P38: =N38-O38 -> 0 | Q38: 0 | S38: =Q38-R38 -> 0 | T38: 0 | V38: =T38-U38 -> 0 | W38: 0 | Y38: =W38-X38 -> 0 | Z38: 0 | AB38: =Z38-AA38 -> 0 | AC38: 50 | AE38: =AC38-AD38 -> 50
A39: 37 | B39: 92111002 | C39: 25 | D39: 10 | E39: HSD DIESEL | F39: HSD DIESEL | G39: LTR | H39: 20 | I39: 0 | J39: =K39+N39+Q39+T39+W39+Z39+AC39 -> 20 | K39: 0 | M39: =K39-L39 -> 0 | N39: 0 | P39: =N39-O39 -> 0 | Q39: 0 | S39: =Q39-R39 -> 0 | T39: 0 | V39: =T39-U39 -> 0 | W39: 0 | Y39: =W39-X39 -> 0 | Z39: 0 | AB39: =Z39-AA39 -> 0 | AC39: 20 | AE39: =AC39-AD39 -> 20
A40: 38 | B40: 85011022 | C40: 24 | D40: 10 | E40: BALL BEARING 6205ZZ | F40: BALL BEARING 6205ZZ | G40: NO. | H40: 20 | I40: 80 | J40: =K40+N40+Q40+T40+W40+Z40+AC40 -> 20 | K40: 0 | M40: =K40-L40 -> 0 | N40: 20 | P40: =N40-O40 -> 20 | Q40: 0 | S40: =Q40-R40 -> 0 | T40: 0 | V40: =T40-U40 -> 0 | W40: 0 | Y40: =W40-X40 -> 0 | Z40: 0 | AB40: =Z40-AA40 -> 0 | AC40: 0 | AE40: =AC40-AD40 -> 0 | AF40: 50 | AG40: 50 | AH40: 80 | AI40: 0
A41: 39 | B41: 64273027 | C41: 24 | D41: 10 | E41: BALL BEARING 6204ZZ | F41: BEARING SINGLE ROW DEEP GROOVE TO 6204ZZ | G41: NO. | H41: 40 | I41: 113 | J41: =K41+N41+Q41+T41+W41+Z41+AC41 -> 0 | K41: 0 | M41: =K41-L41 -> 0 | N41: 0 | P41: =N41-O41 -> 0 | Q41: 0 | S41: =Q41-R41 -> 0 | T41: 0 | V41: =T41-U41 -> 0 | W41: 0 | Y41: =W41-X41 -> 0 | Z41: 0 | AB41: =Z41-AA41 -> 0 | AC41: 0 | AE41: =AC41-AD41 -> 0 | AF41: 35 | AG41: 50 | AH41: 10 | AI41: 0
A42: 40 | B42: 85014813 | C42: 24 | D42: 10 | E42: BALL BEARING NO.6308 | F42: BALL BEARING NO.6308 | G42: NO. | H42: 10 | I42: 45 | J42: =K42+N42+Q42+T42+W42+Z42+AC42 -> 0 | K42: 0 | M42: =K42-L42 -> 0 | N42: 0 | P42: =N42-O42 -> 0 | Q42: 0 | S42: =Q42-R42 -> 0 | T42: 0 | V42: =T42-U42 -> 0 | W42: 0 | Y42: =W42-X42 -> 0 | Z42: 0 | AB42: =Z42-AA42 -> 0 | AC42: 0 | AE42: =AC42-AD42 -> 0 | AF42: 14 | AG42: 28 | AH42: 18 | AI42: 0
A43: 41 | B43: 84115180 | C43: 24 | D43: 70 | E43: ASBESTOS CLOTH | F43: ASBESTOS CLOTH 2MM THICK,1 MTR WIDTH WITH MINIMUM WEIGHT OF 1.25 KG PER METER LENGTH | G43: KG. | H43: 300 | I43: 250 | J43: =K43+N43+Q43+T43+W43+Z43+AC43 -> 300 | K43: 150 | M43: =K43-L43 -> 150 | N43: 100 | P43: =N43-O43 -> 100 | Q43: 50 | S43: =Q43-R43 -> 50 | T43: 0 | V43: =T43-U43 -> 0 | W43: 0 | Y43: =W43-X43 -> 0 | Z43: 0 | AB43: =Z43-AA43 -> 0 | AC43: 0 | AE43: =AC43-AD43 -> 0
A44: 42 | B44: 80090280 | C44: 25 | D44: 70 | E44: TRANSFORMER OIL 200 OR 210 LITRS DRUMS | F44: TRANSFORMER OIL 200 OR 210 LITRS DRUMS | G44: LTR | H44: 11000 | I44: 8200 | J44: =K44+N44+Q44+T44+W44+Z44+AC44 -> 11000 | K44: 11000 | M44: =K44-L44 -> 11000 | N44: 0 | P44: =N44-O44 -> 0 | Q44: 0 | S44: =Q44-R44 -> 0 | T44: 0 | V44: =T44-U44 -> 0 | W44: 0 | Y44: =W44-X44 -> 0 | Z44: 0 | AB44: =Z44-AA44 -> 0 | AC44: 0 | AE44: =AC44-AD44 -> 0
...

Sheet APRIL 2026
A1: S.NO. | B1: SECTION | C1: PL NO. | D1: ITEM SHORT DESCRIPTION | E1: DRAWN
A2: 1 | B2: EMR | C2: 40050178 | D2: =VLOOKUP(C2,'PL NO.'!$B$3:$Q$374,4,0) -> COPPER CABLE, 25SQ.MM, 4 CORE, ARMOURED | E2: 50
A3: 2 | B3: SHIFT/EWFPS | C3: 40120211 | D3: =VLOOKUP(C3,'PL NO.'!$B$3:$Q$374,4,0) -> COMPENSATING CABLE, 'S' TYPE, 1.5 SQ.MM, 2 CORE | E3: 50
A4: 3 | B4: EMR | C4: 40124794 | D4: =VLOOKUP(C4,'PL NO.'!$B$3:$Q$374,4,0) -> COPPER CABLE, 1 SQ.MM TEFLON INSULATED, RED COLOUR | E4: 100
A5: 4 | B5: EMS | C5: 40124800 | D5: =VLOOKUP(C5,'PL NO.'!$B$3:$Q$374,4,0) -> BUTYL RUBBER 95SQMM,1 CORE CABLE FOR EOT CRANE | E5: 100
A6: 5 | B6: EMS | C6: 40124861 | D6: =VLOOKUP(C6,'PL NO.'!$B$3:$Q$374,4,0) -> BUTYL RUBBER 70SQMM, 2 CORE CABLE FOR EOT CRANE | E6: 25
A7: 6 | B7: EMS | C7: 40125555 | D7: =VLOOKUP(C7,'PL NO.'!$B$3:$Q$374,4,0) -> WATER COOLED CABLE FOR EAF | E7: 6
A8: 7 | B8: EMR | C8: 41011466 | D8: =VLOOKUP(C8,'PL NO.'!$B$3:$Q$374,4,0) -> GLASS EPOXY SHEET | E8: 50
A9: 8 | B9: EMS | C9: 41077763 | D9: =VLOOKUP(C9,'PL NO.'!$B$3:$Q$374,4,0) -> PRESSURE SENSITIVE ADHESIVE PVC TAPES BLUE COLOUR | E9: 500
A10: 9 | B10: EWFPS | C10: 41077763 | D10: =VLOOKUP(C10,'PL NO.'!$B$3:$Q$374,4,0) -> PRESSURE SENSITIVE ADHESIVE PVC TAPES BLUE COLOUR | E10: 800
A11: 10 | B11: SHIFT/EMR | C11: 41077763 | D11: =VLOOKUP(C11,'PL NO.'!$B$3:$Q$374,4,0) -> PRESSURE SENSITIVE ADHESIVE PVC TAPES BLUE COLOUR | E11: 200
A12: 11 | B12: SHIFT/EMS | C12: 41077763 | D12: =VLOOKUP(C12,'PL NO.'!$B$3:$Q$374,4,0) -> PRESSURE SENSITIVE ADHESIVE PVC TAPES BLUE COLOUR | E12: 300
A13: 12 | B13: SHIFT/EWFPS | C13: 41077763 | D13: =VLOOKUP(C13,'PL NO.'!$B$3:$Q$374,4,0) -> PRESSURE SENSITIVE ADHESIVE PVC TAPES BLUE COLOUR | E13: 100
... A90: 89 | B90: EMS | C90: 83049400 | D90: =VLOOKUP(C90,'PL NO.'!$B$3:$Q$374,4,0) -> PAPER PHOTOCOPIER | E90: 1

Sheet MAY 2026
A1: S.NO. | B1: SECTION | C1: PL NO. | D1: ITEM SHORT DESCRIPTION | E1: DRAWN
A2: 1 | B2: EMR | C2: 47050019 | D2: =VLOOKUP(C2,'PL NO.'!$B$3:$Q$374,4,0) -> 3HP, 4P, 100L, 72RPM RIGHT ANGLED FOOT MOUNTED IEC GEARED MOTOR | E2: 5
A3: 2 | B3: SHIFT/EWFPS | C3: 42113234 | D3: =VLOOKUP(C3,'PL NO.'!$B$3:$Q$374,4,0) -> PIGMY LAMPS 15W 230V AC | E3: 2
A4: 3 | B4: EMS | C4: 46150079 | D4: =VLOOKUP(C4,'PL NO.'!$B$3:$Q$374,4,0) -> 12KV, 26.3K/3SEC, 1250A, VCB OF SIEMENS MAKE TYPE: 3AHO | E4: 2
A5: 4 | B5: EMS | C5: 47241573 | D5: =VLOOKUP(C5,'PL NO.'!$B$3:$Q$374,4,0) -> JOYSTIC CONTROLLER | E5: 3
A6: 5 | B6: EMS | C6: 47050214 | D6: =VLOOKUP(C6,'PL NO.'!$B$3:$Q$374,4,0) -> 2HP, 4P, 90L, FLANGE MOUNTED SQ CAGE INDUCTION MOTOR WITH BRAKE | E6: 1
A7: 6 | B7: EMS | C7: 47050676 | D7: =VLOOKUP(C7,'PL NO.'!$B$3:$Q$374,4,0) -> 5HP, 6P, 132S, FOOT MOUNTED SQ CAGE INDUCTION MOTOR | E7: 2
A8: 7 | B8: EGS | C8: 83057262 | D8: =VLOOKUP(C8,'PL NO.'!$B$3:$Q$374,4,0) -> FILE COVERS CARD BOARD THIN | E8: 50
A9: 8 | B9: EMR | C9: 46120324 | D9: =VLOOKUP(C9,'PL NO.'!$B$3:$Q$374,4,0) -> COPPER BUS BAR FOR SPRUE WASH | E9: 13
A10: 9 | B10: EMR | C10: 41011466 | D10: =VLOOKUP(C10,'PL NO.'!$B$3:$Q$374,4,0) -> GLASS EPOXY SHEET | E10: 50
A11: 10 | B11: EMR | C11: 47380056 | D11: =VLOOKUP(C11,'PL NO.'!$B$3:$Q$374,4,0) -> TUBE HOLDING OVEN HEATING ELEMENT | E11: 6
A12: 11 | B12: EMR | C12: 47241512 | D12: =VLOOKUP(C12,'PL NO.'!$B$3:$Q$374,4,0) -> MPCB, RATED CURRENT 6A, CURRENT SETTING 4- 6A | E12: 10
A13: 12 | B13: EMR | C13: 45219138 | D13: =VLOOKUP(C13,'PL NO.'!$B$3:$Q$374,4,0) -> POWER CONTACTOR, 16A, 110V AC | E13: 10
... A91: 90 | B91: EMR | C91: 43010076 | D91: =VLOOKUP(C91,'PL NO.'!$B$3:$Q$374,4,0) -> HEATER CARTRIDGES 1500W FOR CORE BAKING | E91: 60
